Workbook

Sheet ENE24
B1: SISTEMA
B2: CONTRATO | C2: FECHA | D2: MONTO | K2: VIIN000000000001 | L2: VIIN000000000003 | M2: VIIN000000000006
B3: 105433 | C3: 44927 | D3: 27001993 | K3: 14913833 | L3: 56950.76 | M3: 12050929 | N3: =SUM(K3:M3) -> 27021713 | O3: =+D3-N3 -> -19720.43
B4: 105433 | C4: 44928 | D4: 27046728 | K4: 14921682 | L4: 56422 | M4: 12065257 | N4: =SUM(K4:M4) -> 27043361 | O4: =+D4-N4 -> 3367.22
B5: 105433 | C5: 44929 | D5: 27059879 | K5: 14934450 | L5: 56323.75 | M5: 12068843 | N5: =SUM(K5:M5) -> 27059617 | O5: =+D5-N5 -> 262.44
B6: 105433 | C6: 44930 | D6: 27016783 | K6: 14907739 | L6: 56009.64 | M6: 12053014 | N6: =SUM(K6:M6) -> 27016763 | O6: =+D6-N6 -> 19.85
B7: 105433 | C7: 44931 | D7: 26989360 | K7: 14910053 | L7: 55990 | M7: 12056596 | N7: =SUM(K7:M7) -> 27022639 | O7: =+D7-N7 -> -33279.69
A8: SAB | B8: 105433 | C8: 44932 | D8: 26989360 | K8: 14910053 | L8: 55990 | M8: 12056596 | N8: =SUM(K8:M8) -> 27022639 | O8: =+D8-N8 -> -33279.69
A9: DOM | B9: 105433 | C9: 44933 | D9: 26989360 | K9: 14910053 | L9: 55990 | M9: 12056596 | N9: =SUM(K9:M9) -> 27022639 | O9: =+D9-N9 -> -33279.69
B10: 105433 | C10: 44934 | D10: 26997534 | K10: 14864658 | L10: 56145.77 | M10: 12067347 | N10: =SUM(K10:M10) -> 26988150 | O10: =+D10-N10 -> 9383.33
B11: 105433 | C11: 44935 | D11: 27034407 | K11: 14909324 | L11: 56061.9 | M11: 12070933 | N11: =SUM(K11:M11) -> 27036320 | O11: =+D11-N11 -> -1913.19
B12: 105433 | C12: 44936 | D12: 27055099 | K12: 14922524 | L12: 56037.47 | M12: 12074521 | N12: =SUM(K12:M12) -> 27053082 | O12: =+D12-N12 -> 2016.43
B13: 105433 | C13: 44937 | D13: 27075760 | K13: 14926826 | L13: 56064.88 | M13: 12078110 | N13: =SUM(K13:M13) -> 27061001 | O13: =+D13-N13 -> 14759.02
B14: 105433 | C14: 44938 | D14: 27065819 | K14: 14918718 | L14: 56078.3 | M14: 12081700 | N14: =SUM(K14:M14) -> 27056496 | O14: =+D14-N14 -> 9322.92
A15: SAB | B15: 105433 | C15: 44939 | D15: 27065819 | K15: 14918718 | L15: 56078.3 | M15: 12081700 | N15: =SUM(K15:M15) -> 27056496 | O15: =+D15-N15 -> 9322.92
A16: DOM | B16: 105433 | C16: 44940 | D16: 27065819 | K16: 14918718 | L16: 56078.3 | M16: 12081700 | N16: =SUM(K16:M16) -> 27056496 | O16: =+D16-N16 -> 9322.92
B17: 105433 | C17: 44941 | D17: 27094544 | K17: 14931458 | L17: 56118.75 | M17: 12092473 | N17: =SUM(K17:M17) -> 27080049 | O17: =+D17-N17 -> 14494.26
B18: 105433 | C18: 44942 | D18: 27152832 | K18: 14935911 | L18: 56142.23 | M18: 12096067 | N18: =SUM(K18:M18) -> 27088120 | O18: =+D18-N18 -> 64711.18
B19: 105433 | C19: 44943 | D19: 27176225 | K19: 15012809 | L19: 56023.2 | M19: 12099662 | N19: =SUM(K19:M19) -> 27168494 | O19: =+D19-N19 -> 7730.67
B20: 105433 | C20: 44944 | D20: 27164869 | K20: 15010323 | L20: 56040.16 | M20: 12103258 | N20: =SUM(K20:M20) -> 27169622 | O20: =+D20-N20 -> -4752.69
B21: 105433 | C21: 44945 | D21: 27152471 | K21: 14981041 | L21: 56247.04 | M21: 12106856 | N21: =SUM(K21:M21) -> 27144144 | O21: =+D21-N21 -> 8326.91
A22: SAB | B22: 105433 | C22: 44946 | D22: 27152471 | K22: 14981041 | L22: 56247.04 | M22: 12106856 | N22: =SUM(K22:M22) -> 27144144 | O22: =+D22-N22 -> 8326.91
A23: DOM | B23: 105433 | C23: 44947 | D23: 27152471 | K23: 14981041 | L23: 56247.04 | M23: 12106856 | N23: =SUM(K23:M23) -> 27144144 | O23: =+D23-N23 -> 8326.91
B24: 105433 | C24: 44948 | D24: 27170043 | K24: 15008564 | L24: 56293.87 | M24: 12117651 | N24: =SUM(K24:M24) -> 27182509 | O24: =+D24-N24 -> -12465.98
B25: 105433 | C25: 44949 | D25: 27230163 | K25: 15046304 | L25: 56380.25 | M25: 12121252 | N25: =SUM(K25:M25) -> 27223937 | O25: =+D25-N25 -> 6226.26
B26: 105433 | C26: 44950 | D26: 27191922 | K26: 15048842 | L26: 56395.79 | M26: 12124855 | N26: =SUM(K26:M26) -> 27230093 | O26: =+D26-N26 -> -38171.24
B27: 105433 | C27: 44951 | D27: 27223079 | K27: 15031979 | L27: 56587.83 | M27: 12128459 | N27: =SUM(K27:M27) -> 27217026 | O27: =+D27-N27 -> 6052.69
B28: 105433 | C28: 44952 | D28: 27211226 | K28: 15019649 | L28: 56702.11 | M28: 12132064 | N28: =SUM(K28:M28) -> 27208415 | O28: =+D28-N28 -> 2810.63
A29: SAB | B29: 105433 | C29: 44953 | D29: 27211226 | K29: 15019649 | L29: 56702.11 | M29: 12132064 | N29: =SUM(K29:M29) -> 27208415 | O29: =+D29-N29 -> 2810.63
A30: DOM | B30: 105433 | C30: 44954 | D30: 27211226 | K30: 15019649 | L30: 56702.11 | M30: 12132064 | N30: =SUM(K30:M30) -> 27208415 | O30: =+D30-N30 -> 2810.63
B31: 105433 | C31: 44955 | D31: 27247200 | K31: 15021586 | L31: 56740.27 | M31: 12142881 | N31: =SUM(K31:M31) -> 27221207 | O31: =+D31-N31 -> 25992.35
B32: 105433 | C32: 44956 | D32: 27241899 | K32: 15031190 | L32: 56827.11 | M32: 12146491 | N32: =SUM(K32:M32) -> 27234507 | O32: =+D32-N32 -> 7391.73
B33: 105433 | C33: 44957 | D33: 27253055 | K33: 15048549 | L33: 57459.47 | M33: 12150101 | N33: =SUM(K33:M33) -> 27256109 | O33: =+D33-N33 -> -3054.43
B35: Dias Prom | C35: 31 | D35: =AVERAGE(D3:D33) -> 27119053 | K35: =AVERAGE(K3:K32) -> 14962280 | L35: =AVERAGE(L3:L32) -> 56287.266 | M35: =AVERAGE(M3:M32) -> 12094455 | N35: =SUM(K35:M35) -> 27113022 | O35: =N35-D35 -> -6030.942
B36: Cobro % | C36: 1.62 | D36: =+D35*$C$37 -> 37831.079 | E36: =D36*1.16 -> 43884.051 | K36: =((((+K35*$C$37))))*1.00022243710193 -> 20877.023 | L36: =((((+L35*$C$37))))*1.00022243710193 -> 78.538202 | M36: =((((+M35*$C$37))))*1.00022243710193 -> 16875.518 | N36: =SUM(K36:M36) -> 37831.079 | O36: =+D36/N36 -> 1
B37: Periodo | C37: =C36/360*C35/100 -> 0.001395 | E37: =E36-D36 -> 6052.9726 | N37: =+D36/N36 -> 1

Sheet FEB24
A1: SISTEMA
A2: CONTRATO | B2: FECHA | C2: MONTO | J2: VIIN000000000001 | K2: VIIN000000000003 | L2: VIIN000000000006
A3: 105433 | B3: 45323 | C3: 27205299 | J3: 15031542 | K3: 56760.62 | L3: 12134136 | M3: =SUM(J3:L3) -> 27222439 | N3: =+C3-M3 -> -17139.8
A4: 105433 | B4: 45324 | C4: 27196495 | J4: 15005286 | K4: 56903.38 | L4: 12137743 | M4: =SUM(J4:L4) -> 27199933 | N4: =+C4-M4 -> -3438.1
A5: 105433 | B5: 45325 | C5: 27196495 | J5: 15005286 | K5: 56903.38 | L5: 12137743 | M5: =SUM(J5:L5) -> 27199933 | N5: =+C5-M5 -> -3438.1
A6: 105433 | B6: 45326 | C6: 27196495 | J6: 15005286 | K6: 56903.38 | L6: 12137743 | M6: =SUM(J6:L6) -> 27199933 | N6: =+C6-M6 -> -3438.1
A7: 105433 | B7: 45327 | C7: 27196495 | J7: 15005286 | K7: 56903.38 | L7: 12137743 | M7: =SUM(J7:L7) -> 27199933 | N7: =+C7-M7 -> -3438.1
A8: 105433 | B8: 45328 | C8: 27193573 | J8: 14984719 | K8: 56967.74 | L8: 12152173 | M8: =SUM(J8:L8) -> 27193860 | N8: =+C8-M8 -> -287.09
A9: 105433 | B9: 45329 | C9: 27201903 | J9: 14988495 | K9: 56990.053 | L9: 12155785 | M9: =SUM(J9:L9) -> 27201270 | N9: =+C9-M9 -> 632.86
A10: 105433 | B10: 45330 | C10: 27236497 | J10: 15021526 | K10: 56920.9 | L10: 12159398 | M10: =SUM(J10:L10) -> 27237845 | N10: =+C10-M10 -> -1348.22
A11: 105433 | B11: 45331 | C11: 27236093 | J11: 15015333 | K11: 56890.47 | L11: 12163012 | M11: =SUM(J11:L11) -> 27235236 | N11: =+C11-M11 -> 857.85
A12: 105433 | B12: 45332 | C12: 27236093 | J12: 15015333 | K12: 56890.47 | L12: 12163012 | M12: =SUM(J12:L12) -> 27235236 | N12: =+C12-M12 -> 857.85
A13: 105433 | B13: 45333 | C13: 27236093 | J13: 15015333 | K13: 56890.47 | L13: 12163012 | M13: =SUM(J13:L13) -> 27235236 | N13: =+C13-M13 -> 857.85
A14: 105433 | B14: 45334 | C14: 27251484 | J14: 15018624 | K14: 56910.2 | L14: 12173857 | M14: =SUM(J14:L14) -> 27249392 | N14: =+C14-M14 -> 2092.1
... A20: 105433 | B20: 45340 | C20: 27255290 | J20: 15013468 | K20: 56886.8 | L20: 12189276 | M20: =SUM(J20:L20) -> 27259631 | N20: =+C20-M20 -> -4341.15
A21: 105433 | B21: 45341 | C21: 27281565 | M21: =SUM(J21:L21) -> 0 | N21: =+C21-M21 -> 27281565
A22: 105433 | B22: 45342 | C22: 27287488 | J22: 15031800 | K22: 56553.503 | L22: 12203929 | M22: =SUM(J22:L22) -> 27292282 | N22: =+C22-M22 -> -4794.3199
A23: 105433 | B23: 45343 | C23: 27288946 | J23: 15022282 | K23: 56538.44 | L23: 12198512 | M23: =SUM(J23:L23) -> 27277333 | N23: =+C23-M23 -> 11613.28
A24: 105433 | B24: 45344 | C24: 27306812 | J24: 15042770 | K24: 56628.84 | L24: 12203245 | M24: =SUM(J24:L24) -> 27302644 | N24: =+C24-M24 -> 4168.13
A25: 105433 | B25: 45345 | C25: 27316907 | J25: 15053367 | K25: 56467.958 | L25: 12205958 | M25: =SUM(J25:L25) -> 27315793 | N25: =+C25-M25 -> 1114.67
A26: 105433 | B26: 45346 | C26: 27316907 | J26: 15053367 | K26: 56467.958 | L26: 12205958 | M26: =SUM(J26:L26) -> 27315793 | N26: =+C26-M26 -> 1114.67
A27: 105433 | B27: 45347 | C27: 27316907 | J27: 15053367 | K27: 56467.958 | L27: 12205958 | M27: =SUM(J27:L27) -> 27315793 | N27: =+C27-M27 -> 1114.67
A28: 105433 | B28: 45348 | C28: 27326688 | J28: 15050173 | K28: 56480.755 | L28: 12212395 | M28: =SUM(J28:L28) -> 27319049 | N28: =+C28-M28 -> 7639.69
A29: 105433 | B29: 45349 | C29: 27326656 | J29: 14945902 | K29: 56241.77 | L29: 12320466 | M29: =SUM(J29:L29) -> 27322610 | N29: =+C29-M29 -> 4045.86
A30: 105433 | B30: 45350 | C30: 27346678 | J30: 14971720 | K30: 56073.32 | L30: 12328692 | M30: =SUM(J30:L30) -> 27356485 | N30: =+C30-M30 -> -9807.62
A31: 105433 | B31: 45351 | C31: 27348368 | J31: 14975769 | K31: 56699.28 | L31: 12332569 | M31: =SUM(J31:L31) -> 27365037 | N31: =+C31-M31 -> -16668.86
A33: Dias Prom | B33: 29 | C33: =AVERAGE(C3:C31) -> 27261448 | J33: =AVERAGE(J3:J31) -> 15015062 | K33: =AVERAGE(K3:K31) -> 56733.505 | L33: =AVERAGE(L3:L31) -> 12190863 | M33: =SUM(J33:L33) -> 27262658 | N33: =M33-C33 -> 1210.1032
A34: Cobro % | B34: 1.62 | C34: =+C33*$B$35 -> 35576.189 | D34: =C34*1.16 -> 41268.38 | J34: =((((+J33*$B$35))))*1.00022243710193 -> 19599.014 | K34: =((((+K33*$B$35))))*1.00022243710193 -> 74.053692 | L34: =((((+L33*$B$35))))*1.00022243710193 -> 15912.615 | M34: =SUM(J34:L34) -> 35585.682 | N34: =+C34/M34 -> 0.99973324
A35: Periodo | B35: =B34/360*B33/100 -> 0.001305 | D35: =D34-C34 -> 5692.1903 | M35: =M34/C34 -> 1.0002668

Sheet MAR24
A1: SISTEMA
A2: CONTRATO | B2: FECHA | C2: MONTO | J2: VIIN000000000001 | K2: VIIN000000000003 | L2: VIIN000000000006
A3: 105433 | B3: 45352 | C3: 27345919 | J3: 14963691 | K3: 56137.29 | L3: 12334662 | M3: =SUM(J3:L3) -> 27354491 | N3: =+C3-M3 -> -8572.1
A4: 105433 | B4: 45353 | C4: 27345919 | J4: 14963691 | K4: 56137.29 | L4: 12334662 | M4: =SUM(J4:L4) -> 27354491 | N4: =+C4-M4 -> -8572.1
A5: 105433 | B5: 45354 | C5: 27345919 | J5: 14963691 | K5: 56137.29 | L5: 12334662 | M5: =SUM(J5:L5) -> 27354491 | N5: =+C5-M5 -> -8572.1
A6: 105433 | B6: 45355 | C6: 27360374 | J6: 14943340 | K6: 56246.09 | L6: 12349715 | M6: =SUM(J6:L6) -> 27349301 | N6: =+C6-M6 -> 11073.45
A7: 105433 | B7: 45356 | C7: 27356216 | J7: 14952754 | K7: 56373.96 | L7: 12352253 | M7: =SUM(J7:L7) -> 27361381 | N7: =+C7-M7 -> -5165.57
A8: 105433 | B8: 45357 | C8: 27360391 | J8: 14952754 | K8: 56373.96 | L8: 12352253 | M8: =SUM(J8:L8) -> 27361381 | N8: =+C8-M8 -> -990.17
A9: 105433 | B9: 45358 | C9: 27327078 | J9: 14936078 | K9: 56280.25 | L9: 12328129 | M9: =SUM(J9:L9) -> 27320487 | N9: =+C9-M9 -> 6591.11
A10: 105433 | B10: 45359 | C10: 27336608 | J10: 15029628 | K10: 56582.111 | L10: 12234265 | M10: =SUM(J10:L10) -> 27320475 | N10: =+C10-M10 -> 16132.7
A11: 105433 | B11: 45360 | C11: 27336608 | J11: 15029628 | K11: 56582.111 | L11: 12234265 | M11: =SUM(J11:L11) -> 27320475 | N11: =+C11-M11 -> 16132.7
A12: 105433 | B12: 45361 | C12: 27336608 | J12: 15029628 | K12: 56582.111 | L12: 12234265 | M12: =SUM(J12:L12) -> 27320475 | N12: =+C12-M12 -> 16132.7
A13: 105433 | B13: 45362 | C13: 27342513 | J13: 14967747 | K13: 56848.85 | L13: 12319469 | M13: =SUM(J13:L13) -> 27344065 | N13: =+C13-M13 -> -1552.05
A14: 105433 | B14: 45363 | C14: 27342023 | J14: 14946882 | K14: 56879.969 | L14: 12334270 | M14: =SUM(J14:L14) -> 27338032 | N14: =+C14-M14 -> 3991.5099
A15: 105433 | B15: 45364 | C15: 27334262 | J15: 14946382 | K15: 56879.711 | L15: 12335176 | M15: =SUM(J15:L15) -> 27338438 | N15: =+C15-M15 -> -4175.8401
A16: 105433 | B16: 45365 | C16: 27331185 | G16: =J15/$C$15 -> 0.54680028 | H16: =K15/$C$15 -> 0.0020808943 | I16: =L15/$C$15 -> 0.45127159 | J16: =$C$16*G16 -> 14944699 | K16: =$C$16*H16 -> 56873.307 | L16: =$C$16*I16 -> 12333787 | M16: =SUM(J16:L16) -> 27335360 | N16: =+C16-M16 -> -4175.37
A17: 105433 | B17: 45366 | C17: 27345046 | G17: =J16/$C$16 -> 0.54680028 | H17: =K16/$C$16 -> 0.0020808943 | I17: =L16/$C$16 -> 0.45127159 | J17: =$C$17*G17 -> 14952279 | K17: =$C$17*H17 -> 56902.151 | L17: =$C$17*I17 -> 12340042 | M17: =SUM(J17:L17) -> 27349223 | N17: =+C17-M17 -> -4177.4875
A18: 105433 | B18: 45367 | C18: 27345046 | G18: =J17/$C$17 -> 0.54680028 | H18: =K17/$C$17 -> 0.0020808943 | I18: =L17/$C$18 -> 0.45127159 | J18: =$C$17*G18 -> 14952279 | K18: =$C$17*H18 -> 56902.151 | L18: =$C$17*I18 -> 12340042 | M18: =SUM(J18:L18) -> 27349223 | N18: =+C18-M18 -> -4177.4875
A19: 105433 | B19: 45368 | C19: 27345046 | G19: =J18/$C$17 -> 0.54680028 | H19: =K18/$C$17 -> 0.0020808943 | I19: =L18/$C$18 -> 0.45127159 | J19: =$C$19*G19 -> 14952279 | K19: =$C$17*H19 -> 56902.151 | L19: =$C$17*I19 -> 12340042 | M19: =SUM(J19:L19) -> 27349223 | N19: =+C19-M19 -> -4177.4875
A20: 105433 | B20: 45369 | C20: 27345046 | G20: =J19/$C$20 -> 0.54680028 | H20: =K19/$C$20 -> 0.0020808943 | I20: =L19/$C$20 -> 0.45127159 | J20: =$C$20*G20 -> 14952279 | K20: =$C$20*H20 -> 56902.151 | L20: =$C$20*I20 -> 12340042 | M20: =SUM(J20:L20) -> 27349223 | N20: =+C20-M20 -> -4177.4875
A21: 105433 | B21: 45370 | C21: 27364947 | G21: =J20/$C$20 -> 0.54680028 | H21: =K20/$C$20 -> 0.0020808943 | I21: =L20/$C$20 -> 0.45127159 | J21: =$C$21*G21 -> 14963161 | K21: =$C$21*H21 -> 56943.564 | L21: =$C$21*I21 -> 12349023 | M21: =SUM(J21:L21) -> 27369128 | N21: =+C21-M21 -> -4180.5279
A22: 105433 | B22: 45371 | C22: 27364496 | G22: =J21/C21 -> 0.54680028 | J22: 14994874 | K22: 57396.674 | L22: 12415699 | M22: =SUM(J22:L22) -> 27467970 | N22: =+C22-M22 -> -103473.05
A23: 105433 | B23: 45372 | C23: 27389943 | G23: =J22/$C$22 -> 0.54796821 | H23: =K22/$C$23 -> 0.0020955383 | I23: =L22/$C$23 -> 0.45329407 | J23: =$C$23*G23 -> 15008818 | K23: =$C$23*H23 -> 57396.674 | L23: =$C$23*I23 -> 12415699 | M23: =SUM(J23:L23) -> 27481913 | N23: =+C23-M23 -> -91970.518
A24: 105433 | B24: 45373 | C24: 27415714 | G24: =J23/$C$23 -> 0.54796821 | H24: =K23/$C$23 -> 0.0020955383 | I24: =L23/$C$23 -> 0.45329407 | J24: =$C$24*G24 -> 15022940 | K24: =$C$24*H24 -> 57450.678 | L24: =$C$24*I24 -> 12427381 | M24: =SUM(J24:L24) -> 27507771 | N24: =+C24-M24 -> -92057.053
A25: 105433 | B25: 45374 | C25: 27415714 | G25: =J24/$C$24 -> 0.54796821 | H25: =K24/$C$24 -> 0.0020955383 | I25: =L24/$C$24 -> 0.45329407 | J25: =$C$25*G25 -> 15022940 | K25: =$C$25*H25 -> 57450.678 | L25: =$C$25*I25 -> 12427381 | M25: =SUM(J25:L25) -> 27507771 | N25: =+C25-M25 -> -92057.053
A26: 105433 | B26: 45375 | C26: 27415714 | G26: =J25/$C$25 -> 0.54796821 | H26: =K25/$C$25 -> 0.0020955383 | I26: =L25/$C$25 -> 0.45329407 | J26: =$C$26*G26 -> 15022940 | K26: =$C$26*H26 -> 57450.678 | L26: =$C$26*I26 -> 12427381 | M26: =SUM(J26:L26) -> 27507771 | N26: =+C26-M26 -> -92057.053
A27: 105433 | B27: 45376 | C27: 27380441 | G27: =J26/$C$26 -> 0.54796821 | H27: =K26/$C$26 -> 0.0020955383 | I27: =L26/$C$26 -> 0.45329407 | J27: =$C$27*G27 -> 15003611 | K27: =$C$27*H27 -> 57376.763 | L27: =$C$27*I27 -> 12411392 | M27: =SUM(J27:L27) -> 27472380 | N27: =+C27-M27 -> -91938.614
A28: 105433 | B28: 45377 | C28: 27386634 | G28: =J27/$C$27 -> 0.54796821 | H28: =K27/$C$27 -> 0.0020955383 | I28: =L27/$C$27 -> 0.45329407 | J28: =$C$28*G28 -> 15007005 | K28: =$C$28*H28 -> 57389.74 | L28: =$C$28*I28 -> 12414199 | M28: =SUM(J28:L28) -> 27478593 | N28: =+C28-M28 -> -91959.407
A29: 105433 | B29: 45378 | C29: 27402974 | J29: 14934047 | K29: 57676.804 | L29: 12380854 | M29: =SUM(J29:L29) -> 27372577 | N29: =+C29-M29 -> 30396.38
A30: 105433 | B30: 45379 | C30: 27402974 | G30: =$J$29/C29 -> 0.54497906 | H30: =$K$29/C29 -> 0.0021047644 | I30: =$L$29/C29 -> 0.45180694 | J30: =$C$30*G30 -> 14934047 | K30: =$C$30*H30 -> 57676.804 | L30: =$C$30*I30 -> 12380854 | M30: =SUM(J30:L30) -> 27372577 | N30: =+C30-M30 -> 30396.38
A31: 105433 | B31: 45380 | C31: 27402974 | G31: =$J$29/C30 -> 0.54497906 | H31: =$K$29/C30 -> 0.0021047644 | I31: =$L$30/C30 -> 0.45180694 | J31: =$C$31*G31 -> 14934047 | K31: =$C$31*H31 -> 57676.804 | L31: =$C$31*I31 -> 12380854 | M31: =SUM(J31:L31) -> 27372577 | N31: =+C31-M31 -> 30396.38
A32: 105434 | B32: 45381 | C32: 27402974 | G32: =$J$29/C31 -> 0.54497906 | H32: =$K$29/C31 -> 0.0021047644 | I32: =$L$31/C31 -> 0.45180694 | J32: =$C$32*G32 -> 14934047 | K32: =$C$32*H32 -> 57676.804 | L32: =$C$32*I32 -> 12380854 | M32: =SUM(J32:L32) -> 27372577 | N32: =+C32-M32 -> 30396.38
A33: 105435 | B33: 45382 | C33: 27402974 | G33: =$J$29/C32 -> 0.54497906 | H33: =$K$29/C32 -> 0.0021047644 | I33: =$L$32/C33 -> 0.45180694 | J33: =$C$33*G33 -> 14934047 | K33: =$C$33*H33 -> 57676.804 | L33: =$C$33*I33 -> 12380854 | M33: =SUM(J33:L33) -> 27372577 | N33: =+C33-M33 -> 30396.38
A35: Dias Prom | B35: 31 | C35: =AVERAGE(C3:C31) -> 27362908 | J35: =AVERAGE(J3:J31) -> 14973384 | K35: =AVERAGE(K3:K31) -> 56910.647 | L35: =AVERAGE(L3:L31) -> 12351818 | M35: =SUM(J35:L35) -> 27382113 | N35: =M35-C35 -> 19204.663
A36: Cobro % | B36: 1.62 | C36: =+C35*$B$37 -> 38171.257 | D36: =C36*1.16 -> 44278.658 | J36: =(+J35*$B$37)*0.999298642042412 -> 20873.221 | K36: =(+K35*$B$37)*0.999298642042412 -> 79.334672 | L36: =(+L35*$B$37)*0.999298642042412 -> 17218.701 | M36: =SUM(J36:L36) -> 38171.257 | N36: =+C36/M36 -> 1
A37: Periodo | B37: =B36/360*B35/100 -> 0.001395 | D37: =D36-C36 -> 6107.4011 | M37: =C36/M36 -> 1

Sheet ABR24
D1: Inicial | E1: 45382 | F1: 14934047 | G1: 57676.804 | H1: 12380854 | I1: =+F1+G1+H1 -> 27372577
D2: Final | E2: 45412 | F2: 14983704 | G2: 58169.493 | H2: 12376300 | I2: =+F2+G2+H2 -> 27418173
E4: 45382 | F4: =+F1/$I1 -> 0.54558424 | G4: =+G1/$I1 -> 0.0021071017 | H4: =+H1/$I1 -> 0.45230866 | I4: =+F4+G4+H4 -> 1
E5: 45412 | F5: =+F2/$I2 -> 0.54648806 | G5: =+G2/$I2 -> 0.002121567 | H5: =+H2/$I2 -> 0.45139038 | I5: =+F5+G5+H5 -> 1
A6: SISTEMA | E6: Promedio | F6: =AVERAGE(F4:F5) -> 0.54603615 | G6: =AVERAGE(G4:G5) -> 0.0021143344 | H6: =AVERAGE(H4:H5) -> 0.45184952
A7: CONTRATO | B7: FECHA | C7: MONTO | J7: VIIN000000000001 | K7: VIIN000000000003 | L7: VIIN000000000006
A8: 105433 | B8: 45383 | C8: 27411918 | J8: 14967898 | K8: 57957.961 | L8: 12386062 | M8: =SUM(J8:L8) -> 27411918 | N8: =+C8-M8 -> 0
A9: 105433 | B9: 45384 | C9: 27389250 | J9: 14955521 | K9: 57910.033 | L9: 12375820 | M9: =SUM(J9:L9) -> 27389250 | N9: =+C9-M9 -> 0
A10: 105433 | B10: 45385 | C10: 27383265 | J10: 14952252 | K10: 57897.377 | L10: 12373115 | M10: =SUM(J10:L10) -> 27383265 | N10: =+C10-M10 -> 0
A11: 105433 | B11: 45386 | C11: 27351410 | J11: 14934859 | K11: 57830.027 | L11: 12358722 | M11: =SUM(J11:L11) -> 27351410 | N11: =+C11-M11 -> 0
A12: 105433 | B12: 45387 | C12: 27316140 | J12: 14915600 | K12: 57755.455 | L12: 12342785 | M12: =SUM(J12:L12) -> 27316140 | N12: =+C12-M12 -> 0
A13: 105433 | B13: 45388 | C13: 27316140 | J13: 14915600 | K13: 57755.455 | L13: 12342785 | M13: =SUM(J13:L13) -> 27316140 | N13: =+C13-M13 -> 0
A14: 105433 | B14: 45389 | C14: 27316140 | J14: 14915600 | K14: 57755.455 | L14: 12342785 | M14: =SUM(J14:L14) -> 27316140 | N14: =+C14-M14 -> 0
A15: 105433 | B15: 45390 | C15: 27269991 | J15: 14890401 | K15: 57657.88 | L15: 12321932 | M15: =SUM(J15:L15) -> 27269991 | N15: =+C15-M15 -> 0
A16: 105433 | B16: 45391 | C16: 27315518 | J16: 14915260 | K16: 57754.139 | L16: 12342504 | M16: =SUM(J16:L16) -> 27315518 | N16: =+C16-M16 -> 0
A17: 105433 | B17: 45392 | C17: 27256537 | J17: 14883054 | K17: 57629.433 | L17: 12315853 | M17: =SUM(J17:L17) -> 27256537 | N17: =+C17-M17 -> 0
A18: 105433 | B18: 45393 | C18: 27237857 | J18: 14872855 | K18: 57589.938 | L18: 12307413 | M18: =SUM(J18:L18) -> 27237857 | N18: =+C18-M18 -> 0
A19: 105433 | B19: 45394 | C19: 27306971 | J19: 14910593 | K19: 57736.067 | L19: 12338642 | M19: =SUM(J19:L19) -> 27306971 | N19: =+C19-M19 -> 0
... A37: 105434 | B37: 45412 | C37: 27427045 | J37: 14976158 | K37: 57989.944 | L37: 12392897 | M37: =SUM(J37:L37) -> 27427045 | N37: =+C37-M37 -> 0
A39: Dias Prom | B39: =COUNT(B8:B37) -> 30 | C39: =AVERAGE(C8:C37) -> 27373893 | J39: =AVERAGE(J8:J37) -> 14947135 | K39: =AVERAGE(K8:K37) -> 57877.562 | L39: =AVERAGE(L8:L37) -> 12368880 | M39: =SUM(J39:L39) -> 27373893 | N39: =M39-C39 -> 0
A40: Cobro % | B40: 1.62 | C40: =+C39*$B$41 -> 36954.755 | D40: =C40*1.16 -> 42867.516 | J40: =(+J39*$B$41) -> 20178.632 | K40: =(+K39*$B$41) -> 78.134709 | L40: =(+L39*$B$41) -> 16697.988 | M40: =SUM(J40:L40) -> 36954.755 | N40: =+C40/M40 -> 1
A41: Periodo | B41: =B40/360*B39/100 -> 0.00135 | D41: =D40-C40 -> 5912.7609 | J41: 21042.092 | K41: 80.486973 | L41: 17385.216 | M41: =C40/M40 -> 1

Sheet MAY24
D1: Inicial | E1: 45412 | F1: 14983704 | G1: 58169.493 | H1: 12376300 | I1: =+F1+G1+H1 -> 27418173
D2: Final | E2: 45443 | F2: 15174652 | G2: 57176.544 | H2: 12540923 | I2: =+F2+G2+H2 -> 27772751
E4: =+E1 -> 45412 | F4: =+F1/$I1 -> 0.54648806 | G4: =+G1/$I1 -> 0.002121567 | H4: =+H1/$I1 -> 0.45139038 | I4: =+F4+G4+H4 -> 1
E5: =+E2 -> 45443 | F5: =+F2/$I2 -> 0.54638635 | G5: =+G2/$I2 -> 0.0020587281 | H5: =+H2/$I2 -> 0.45155492 | I5: =+F5+G5+H5 -> 1
A6: SISTEMA | E6: Promedio | F6: =AVERAGE(F4:F5) -> 0.5464372 | G6: =AVERAGE(G4:G5) -> 0.0020901476 | H6: =AVERAGE(H4:H5) -> 0.45147265
A7: CONTRATO | B7: FECHA | C7: MONTO | J7: VIIN000000000001 | K7: VIIN000000000003 | L7: VIIN000000000006
A8: 105433 | B8: 45413 | C8: 27427045 | J8: 14987158 | K8: 57326.571 | L8: 12382561 | M8: =SUM(J8:L8) -> 27427045 | N8: =+C8-M8 -> 0
A9: 105433 | B9: 45414 | C9: 27496851 | J9: 15025303 | K9: 57472.477 | L9: 12414076 | M9: =SUM(J9:L9) -> 27496851 | N9: =+C9-M9 -> 0
A10: 105433 | B10: 45415 | C10: 27551417 | J10: 15055119 | K10: 57586.526 | L10: 12438711 | M10: =SUM(J10:L10) -> 27551417 | N10: =+C10-M10 -> 0
A11: 105433 | B11: 45415 | C11: 27551417 | J11: 15055119 | K11: 57586.526 | L11: 12438711 | M11: =SUM(J11:L11) -> 27551417 | N11: =+C11-M11 -> 0
A12: 105433 | B12: 45417 | C12: 27551417 | J12: 15055119 | K12: 57586.526 | L12: 12438711 | M12: =SUM(J12:L12) -> 27551417 | N12: =+C12-M12 -> 0
A13: 105433 | B13: 45418 | C13: 27591670 | J13: 15077115 | K13: 57670.661 | L13: 12456884 | M13: =SUM(J13:L13) -> 27591670 | N13: =+C13-M13 -> 0
A14: 105433 | B14: 45419 | C14: 27580995 | J14: 15071282 | K14: 57648.349 | L14: 12452065 | M14: =SUM(J14:L14) -> 27580995 | N14: =+C14-M14 -> 0
A15: 105433 | B15: 45420 | C15: 27603821 | J15: 15083755 | K15: 57696.06 | L15: 12462370 | M15: =SUM(J15:L15) -> 27603821 | N15: =+C15-M15 -> 0
A16: 105433 | B16: 45421 | C16: 27580091 | J16: 15070788 | K16: 57646.461 | L16: 12451657 | M16: =SUM(J16:L16) -> 27580091 | N16: =+C16-M16 -> 0
A17: 105433 | B17: 45422 | C17: 27565314 | J17: 15062713 | K17: 57615.573 | L17: 12444985 | M17: =SUM(J17:L17) -> 27565314 | N17: =+C17-M17 -> 0
A18: 105433 | B18: 45423 | C18: 27565314 | J18: 15062713 | K18: 57615.573 | L18: 12444985 | M18: =SUM(J18:L18) -> 27565314 | N18: =+C18-M18 -> 0
A19: 105433 | B19: 45424 | C19: 27565314 | J19: 15062713 | K19: 57615.573 | L19: 12444985 | M19: =SUM(J19:L19) -> 27565314 | N19: =+C19-M19 -> 0
... A38: 105434 | B38: 45443 | C38: 27739259 | J38: 15157763 | K38: 57979.144 | L38: 12523517 | M38: =SUM(J38:L38) -> 27739259 | N38: =+C38-M38 -> 0
A40: Dias Prom | B40: =COUNT(B8:B38) -> 31 | C40: =AVERAGE(C8:C38) -> 27604154 | J40: =AVERAGE(J8:J38) -> 15083937 | K40: =AVERAGE(K8:K38) -> 57696.755 | L40: =AVERAGE(L8:L38) -> 12462520 | M40: =SUM(J40:L40) -> 27604154 | N40: =M40-C40 -> 0
A41: Cobro % | B41: 1.62 | C41: =+C40*$B$42 -> 38507.795 | D41: =C41*1.16 -> 44669.042 | J41: =(+J40*$B$42) -> 21042.092 | K41: =(+K40*$B$42) -> 80.486973 | L41: =(+L40*$B$42) -> 17385.216 | M41: =SUM(J41:L41) -> 38507.795 | N41: =+C41/M41 -> 1
A42: Periodo | B42: =B41/360*B40/100 -> 0.001395 | D42: =D41-C41 -> 6161.2471 | M42: =C41/M41 -> 1

Sheet JUN24
D1: Inicial | E1: 45443 | F1: 15174652 | G1: 57176.544 | H1: 12540923 | I1: =+F1+G1+H1 -> 27772751
D2: Final | E2: 45473 | F2: 15576607 | G2: 56795.075 | H2: 12671188 | I2: =+F2+G2+H2 -> 28304591
E4: =+E1 -> 45443 | F4: =+F1/$I1 -> 0.54638635 | G4: =+G1/$I1 -> 0.0020587281 | H4: =+H1/$I1 -> 0.45155492 | I4: =+F4+G4+H4 -> 1
E5: =+E2 -> 45473 | F5: =+F2/$I2 -> 0.55032089 | G5: =+G2/$I2 -> 0.0020065676 | H5: =+H2/$I2 -> 0.44767255 | I5: =+F5+G5+H5 -> 1
A6: SISTEMA | E6: Promedio | F6: =AVERAGE(F4:F5) -> 0.54835362 | G6: =AVERAGE(G4:G5) -> 0.0020326479 | H6: =AVERAGE(H4:H5) -> 0.44961374
A7: CONTRATO | B7: FECHA | C7: MONTO | J7: VIIN000000000001 | K7: VIIN000000000003 | L7: VIIN000000000006
A8: 105433 | B8: 45444 | C8: 27739259 | J8: 15210923 | K8: 56384.145 | L8: 12471952 | M8: =SUM(J8:L8) -> 27739259 | N8: =+C8-M8 -> 0
A9: 105433 | B9: 45445 | C9: 27739259 | J9: 15210923 | K9: 56384.145 | L9: 12471952 | M9: =SUM(J9:L9) -> 27739259 | N9: =+C9-M9 -> 0
A10: 105433 | B10: 45446 | C10: 27949037 | J10: 15325955 | K10: 56810.549 | L10: 12566271 | M10: =SUM(J10:L10) -> 27949037 | N10: =+C10-M10 -> 0
A11: 105433 | B11: 45447 | C11: 28035928 | J11: 15373602 | K11: 56987.168 | L11: 12605338 | M11: =SUM(J11:L11) -> 28035928 | N11: =+C11-M11 -> 0
A12: 105433 | B12: 45448 | C12: 28017688 | J12: 15363600 | K12: 56950.093 | L12: 12597137 | M12: =SUM(J12:L12) -> 28017688 | N12: =+C12-M12 -> 0
A13: 105433 | B13: 45449 | C13: 28094715 | J13: 15405839 | K13: 57106.663 | L13: 12631770 | M13: =SUM(J13:L13) -> 28094715 | N13: =+C13-M13 -> 0
A14: 105433 | B14: 45450 | C14: 28233022 | J14: 15481680 | K14: 57387.792 | L14: 12693954 | M14: =SUM(J14:L14) -> 28233022 | N14: =+C14-M14 -> 0
A15: 105433 | B15: 45451 | C15: 28233022 | J15: 15481680 | K15: 57387.792 | L15: 12693954 | M15: =SUM(J15:L15) -> 28233022 | N15: =+C15-M15 -> 0
A16: 105433 | B16: 45452 | C16: 28233022 | J16: 15481680 | K16: 57387.792 | L16: 12693954 | M16: =SUM(J16:L16) -> 28233022 | N16: =+C16-M16 -> 0
A17: 105433 | B17: 45453 | C17: 28170251 | J17: 15447259 | K17: 57260.199 | L17: 12665732 | M17: =SUM(J17:L17) -> 28170251 | N17: =+C17-M17 -> 0
A18: 105433 | B18: 45454 | C18: 28271453 | J18: 15502753 | K18: 57465.908 | L18: 12711233 | M18: =SUM(J18:L18) -> 28271453 | N18: =+C18-M18 -> 0
A19: 105433 | B19: 45455 | C19: 28379085 | J19: 15561774 | K19: 57684.687 | L19: 12759626 | M19: =SUM(J19:L19) -> 28379085 | N19: =+C19-M19 -> 0
... A37: 105433 | B37: 45473 | C37: 28338888 | J37: 15539732 | K37: 57602.979 | L37: 12741553 | M37: =SUM(J37:L37) -> 28338888 | N37: =+C37-M37 -> 0
A40: Dias Prom | B40: =COUNT(B8:B38) -> 30 | C40: =AVERAGE(C8:C38) -> 28170225 | J40: =AVERAGE(J8:J38) -> 15447245 | K40: =AVERAGE(K8:K38) -> 57260.147 | L40: =AVERAGE(L8:L38) -> 12665720 | M40: =SUM(J40:L40) -> 28170225 | N40: =M40-C40 -> 0
A41: Cobro % | B41: 1.62 | C41: =+C40*$B$42 -> 38029.803 | D41: =C41*1.16 -> 44114.572 | J41: =(+J40*$B$42) -> 20853.78 | K41: =(+K40*$B$42) -> 77.301198 | L41: =(+L40*$B$42) -> 17098.722 | M41: =SUM(J41:L41) -> 38029.803 | N41: =+C41/M41 -> 1
A42: Periodo | B42: =B41/360*B40/100 -> 0.00135 | D42: =D41-C41 -> 6084.7685 | M42: =C41/M41 -> 1
C46: =+C41+'JUL24'!C41+'AGO24'!C41 -> 118291.26

Sheet JUL24
D1: Inicial | E1: 45473 | F1: 15576607 | G1: 56795.075 | H1: 12671188 | I1: =+F1+G1+H1 -> 28304591
D2: Final | E2: 45504 | F2: 15865801 | G2: 56293.67 | H2: 12858361 | I2: =+F2+G2+H2 -> 28780455
E4: =+E1 -> 45473 | F4: =+F1/$I1 -> 0.55032089 | G4: =+G1/$I1 -> 0.0020065676 | H4: =+H1/$I1 -> 0.44767255 | I4: =+F4+G4+H4 -> 1
E5: =+E2 -> 45504 | F5: =+F2/$I2 -> 0.55126997 | G5: =+G2/$I2 -> 0.0019559687 | H5: =+H2/$I2 -> 0.44677406 | I5: =+F5+G5+H5 -> 1
A6: SISTEMA | E6: Promedio | F6: =AVERAGE(F4:F5) -> 0.55079543 | G6: =AVERAGE(G4:G5) -> 0.0019812682 | H6: =AVERAGE(H4:H5) -> 0.4472233
A7: CONTRATO | B7: FECHA | C7: MONTO | J7: VIIN000000000001 | K7: VIIN000000000003 | L7: VIIN000000000006
A8: 105433 | B8: 45474 | C8: 28354830 | J8: 15617711 | K8: 56178.522 | L8: 12680941 | M8: =SUM(J8:L8) -> 28354830 | N8: =+C8-M8 -> 0
A9: 105433 | B9: 45475 | C9: 28270304 | J9: 15571154 | K9: 56011.052 | L9: 12643139 | M9: =SUM(J9:L9) -> 28270304 | N9: =+C9-M9 -> 0
A10: 105433 | B10: 45476 | C10: 28262802 | J10: 15567022 | K10: 55996.19 | L10: 12639784 | M10: =SUM(J10:L10) -> 28262802 | N10: =+C10-M10 -> 0
A11: 105433 | B11: 45477 | C11: 28184375 | J11: 15523825 | K11: 55840.804 | L11: 12604709 | M11: =SUM(J11:L11) -> 28184375 | N11: =+C11-M11 -> 0
A12: 105433 | B12: 45478 | C12: 28209245 | J12: 15537523 | K12: 55890.079 | L12: 12615832 | M12: =SUM(J12:L12) -> 28209245 | N12: =+C12-M12 -> 0
A13: 105433 | B13: 45479 | C13: 28209245 | J13: 15537523 | K13: 55890.079 | L13: 12615832 | M13: =SUM(J13:L13) -> 28209245 | N13: =+C13-M13 -> 0
A14: 105433 | B14: 45480 | C14: 28209245 | J14: 15537523 | K14: 55890.079 | L14: 12615832 | M14: =SUM(J14:L14) -> 28209245 | N14: =+C14-M14 -> 0
A15: 105433 | B15: 45481 | C15: 28217620 | J15: 15542136 | K15: 55906.673 | L15: 12619577 | M15: =SUM(J15:L15) -> 28217620 | N15: =+C15-M15 -> 0
A16: 105433 | B16: 45482 | C16: 28182064 | J16: 15522552 | K16: 55836.226 | L16: 12603676 | M16: =SUM(J16:L16) -> 28182064 | N16: =+C16-M16 -> 0
A17: 105433 | B17: 45483 | C17: 28211553 | J17: 15538795 | K17: 55894.652 | L17: 12616864 | M17: =SUM(J17:L17) -> 28211553 | N17: =+C17-M17 -> 0
A18: 105433 | B18: 45484 | C18: 28241699 | J18: 15555399 | K18: 55954.379 | L18: 12630346 | M18: =SUM(J18:L18) -> 28241699 | N18: =+C18-M18 -> 0
A19: 105433 | B19: 45485 | C19: 28239344 | J19: 15554102 | K19: 55949.713 | L19: 12629293 | M19: =SUM(J19:L19) -> 28239344 | N19: =+C19-M19 -> 0
... A37: 105434 | B37: 45503 | C37: 28827613 | J37: 15878117 | K37: 57115.231 | L37: 12892380 | M37: =SUM(J37:L37) -> 28827613 | N37: =+C37-M37 -> 0
A38: 105435 | B38: 45504 | C38: 28781251 | J38: 15852581 | K38: 57023.375 | L38: 12871646 | M38: =SUM(J38:L38) -> 28781251
A40: Dias Prom | B40: =COUNT(B8:B38) -> 31 | C40: =AVERAGE(C8:C38) -> 28411967 | J40: =AVERAGE(J8:J38) -> 15649182 | K40: =AVERAGE(K8:K38) -> 56291.726 | L40: =AVERAGE(L8:L38) -> 12706494 | M40: =SUM(J40:L40) -> 28411967 | N40: =M40-C40 -> 0
A41: Cobro % | B41: 1.62 | C41: =+C40*$B$42 -> 39634.694 | D41: =C41*1.16 -> 45976.245 | J41: =(+J40*$B$42) -> 21830.608 | K41: =(+K40*$B$42) -> 78.526958 | L41: =(+L40*$B$42) -> 17725.559 | M41: =SUM(J41:L41) -> 39634.694 | N41: =+C41/M41 -> 1
A42: Periodo | B42: =B41/360*B40/100 -> 0.001395 | D42: =D41-C41 -> 6341.5511 | M42: =C41/M41 -> 1

Sheet AGO24
D1: Inicial | E1: 45504 | F1: 15865801 | G1: 56293.67 | H1: 12858361 | I1: =+F1+G1+H1 -> 28780455
D2: Final | E2: 45535 | F2: 16388708 | G2: 57026.26 | H2: 13177047 | I2: =+F2+G2+H2 -> 29622781
E4: =+E1 -> 45504 | F4: =+F1/$I1 -> 0.55126997 | G4: =+G1/$I1 -> 0.0019559687 | H4: =+H1/$I1 -> 0.44677406 | I4: =+F4+G4+H4 -> 1
E5: =+E2 -> 45535 | F5: =+F2/$I2 -> 0.55324677 | G5: =+G2/$I2 -> 0.0019250813 | H5: =+H2/$I2 -> 0.44482814 | I5: =+F5+G5+H5 -> 1
A6: SISTEMA | E6: Promedio | F6: =AVERAGE(F4:F5) -> 0.55225837 | G6: =AVERAGE(G4:G5) -> 0.001940525 | H6: =AVERAGE(H4:H5) -> 0.4458011
A7: CONTRATO | B7: FECHA | C7: MONTO | J7: VIIN000000000001 | K7: VIIN000000000003 | L7: VIIN000000000006
A8: 105433 | B8: 45505 | C8: 28812796 | J8: 15912108 | K8: 55911.95 | L8: 12844776 | M8: =SUM(J8:L8) -> 28812796 | N8: =+C8-M8 -> 0
A9: 105433 | B9: 45506 | C9: 28992190 | J9: 16011180 | K9: 56260.069 | L9: 12924750 | M9: =SUM(J9:L9) -> 28992190 | N9: =+C9-M9 -> 0
A10: 105433 | B10: 45507 | C10: 28992190 | J10: 16011180 | K10: 56260.069 | L10: 12924750 | M10: =SUM(J10:L10) -> 28992190 | N10: =+C10-M10 -> 0
A11: 105433 | B11: 45508 | C11: 28992190 | J11: 16011180 | K11: 56260.069 | L11: 12924750 | M11: =SUM(J11:L11) -> 28992190 | N11: =+C11-M11 -> 0
A12: 105433 | B12: 45509 | C12: 29106426 | J12: 16074268 | K12: 56481.747 | L12: 12975677 | M12: =SUM(J12:L12) -> 29106426 | N12: =+C12-M12 -> 0
A13: 105433 | B13: 45510 | C13: 29125018 | J13: 16084535 | K13: 56517.824 | L13: 12983965 | M13: =SUM(J13:L13) -> 29125018 | N13: =+C13-M13 -> 0
A14: 105433 | B14: 45511 | C14: 29025425 | J14: 16029534 | K14: 56324.562 | L14: 12939566 | M14: =SUM(J14:L14) -> 29025425 | N14: =+C14-M14 -> 0
A15: 105433 | B15: 45512 | C15: 28935857 | J15: 15980069 | K15: 56150.753 | L15: 12899637 | M15: =SUM(J15:L15) -> 28935857 | N15: =+C15-M15 -> 0
A16: 105433 | B16: 45513 | C16: 28903281 | J16: 15962079 | K16: 56087.539 | L16: 12885115 | M16: =SUM(J16:L16) -> 28903281 | N16: =+C16-M16 -> 0
A17: 105433 | B17: 45514 | C17: 28903281 | J17: 15962079 | K17: 56087.539 | L17: 12885115 | M17: =SUM(J17:L17) -> 28903281 | N17: =+C17-M17 -> 0
A18: 105433 | B18: 45515 | C18: 28903281 | J18: 15962079 | K18: 56087.539 | L18: 12885115 | M18: =SUM(J18:L18) -> 28903281 | N18: =+C18-M18 -> 0
A19: 105433 | B19: 45516 | C19: 29007726 | J19: 16019760 | K19: 56290.217 | L19: 12931676 | M19: =SUM(J19:L19) -> 29007726 | N19: =+C19-M19 -> 0
... A37: 105434 | B37: 45534 | C37: 29639715 | J37: 16368781 | K37: 57516.608 | L37: 13213418 | M37: =SUM(J37:L37) -> 29639715 | N37: =+C37-M37 -> 0
A38: 105435 | B38: 45535 | C38: 29639715 | J38: 16368781 | K38: 57516.608 | L38: 13213418 | M38: =SUM(J38:L38) -> 29639715
A40: Dias Prom | B40: =COUNT(B8:B38) -> 31 | C40: =AVERAGE(C8:C38) -> 29123124 | J40: =AVERAGE(J8:J38) -> 16083489 | K40: =AVERAGE(K8:K38) -> 56514.15 | L40: =AVERAGE(L8:L38) -> 12983121 | M40: =SUM(J40:L40) -> 29123124 | N40: =M40-C40 -> 0
A41: Cobro % | B41: 1.62 | C41: =+C40*$B$42 -> 40626.758 | D41: =C41*1.16 -> 47127.04 | J41: =(+J40*$B$42) -> 22436.468 | K41: =(+K40*$B$42) -> 78.837239 | L41: =(+L40*$B$42) -> 18111.454 | M41: =SUM(J41:L41) -> 40626.758 | N41: =+C41/M41 -> 1
A42: Periodo | B42: =B41/360*B40/100 -> 0.001395 | D42: =D41-C41 -> 6500.2813 | M42: =C41/M41 -> 1
M46: =+'JUL24'!M41+'AGO24'!M41+41000 -> 121261.45

Sheet SEP24
D1: Inicial | E1: 45535 | F1: 16388708 | G1: 57026.26 | H1: 13177047 | I1: =+F1+G1+H1 -> 29622781
D2: Final | E2: 45565 | F2: 16529994 | G2: 57263.004 | H2: 13222888 | I2: =+F2+G2+H2 -> 29810144
E4: =+E1 -> 45535 | F4: =+F1/$I1 -> 0.55324677 | G4: =+G1/$I1 -> 0.0019250813 | H4: =+H1/$I1 -> 0.44482814 | I4: =+F4+G4+H4 -> 1
E5: =+E2 -> 45565 | F5: =+F2/$I2 -> 0.55450902 | G5: =+G2/$I2 -> 0.0019209234 | H5: =+H2/$I2 -> 0.44357006 | I5: =+F5+G5+H5 -> 1
A6: SISTEMA | E6: Promedio | F6: =AVERAGE(F4:F5) -> 0.5538779 | G6: =AVERAGE(G4:G5) -> 0.0019230023 | H6: =AVERAGE(H4:H5) -> 0.4441991
A7: CONTRATO | B7: FECHA | C7: MONTO | J7: VIIN000000000001 | K7: VIIN000000000003 | L7: VIIN000000000006
A8: 105433 | B8: 45536 | C8: 29639715 | J8: 16416783 | K8: 56997.242 | L8: 13165935 | M8: =SUM(J8:L8) -> 29639715 | N8: =+C8-M8 -> 0
A9: 105433 | B9: 45537 | C9: 29709633 | J9: 16455509 | K9: 57131.694 | L9: 13196992 | M9: =SUM(J9:L9) -> 29709633 | N9: =+C9-M9 -> 0
A10: 105433 | B10: 45538 | C10: 29661164 | J10: 16428663 | K10: 57038.487 | L10: 13175462 | M10: =SUM(J10:L10) -> 29661164 | N10: =+C10-M10 -> 0
A11: 105433 | B11: 45539 | C11: 29766906 | J11: 16487232 | K11: 57241.83 | L11: 13222433 | M11: =SUM(J11:L11) -> 29766906 | N11: =+C11-M11 -> 0
A12: 105433 | B12: 45540 | C12: 29807901 | J12: 16509937 | K12: 57320.663 | L12: 13240643 | M12: =SUM(J12:L12) -> 29807901 | N12: =+C12-M12 -> 0
A13: 105433 | B13: 45541 | C13: 29844048 | J13: 16529959 | K13: 57390.175 | L13: 13256700 | M13: =SUM(J13:L13) -> 29844048 | N13: =+C13-M13 -> 0
A14: 105433 | B14: 45542 | C14: 29844048 | J14: 16529959 | K14: 57390.175 | L14: 13256700 | M14: =SUM(J14:L14) -> 29844048 | N14: =+C14-M14 -> 0
A15: 105433 | B15: 45543 | C15: 29844048 | J15: 16529959 | K15: 57390.175 | L15: 13256700 | M15: =SUM(J15:L15) -> 29844048 | N15: =+C15-M15 -> 0
A16: 105433 | B16: 45544 | C16: 29896533 | J16: 16559029 | K16: 57491.102 | L16: 13280013 | M16: =SUM(J16:L16) -> 29896533 | N16: =+C16-M16 -> 0
A17: 105433 | B17: 45545 | C17: 30024030 | J17: 16629646 | K17: 57736.279 | L17: 13336647 | M17: =SUM(J17:L17) -> 30024030 | N17: =+C17-M17 -> 0
A18: 105433 | B18: 45546 | C18: 29773840 | J18: 16491072 | K18: 57255.164 | L18: 13225513 | M18: =SUM(J18:L18) -> 29773840 | N18: =+C18-M18 -> 0
A19: 105433 | B19: 45547 | C19: 29510787 | J19: 16345373 | K19: 56749.313 | L19: 13108665 | M19: =SUM(J19:L19) -> 29510787 | N19: =+C19-M19 -> 0
... A37: 105434 | B37: 45565 | C37: 29846323 | J37: 16531219 | K37: 57394.549 | L37: 13257710 | M37: =SUM(J37:L37) -> 29846323 | N37: =+C37-M37 -> 0
A39: Dias Prom | B39: =COUNT(B8:B37) -> 30 | C39: =AVERAGE(C8:C37) -> 29655376 | J39: =AVERAGE(J8:J37) -> 16425457 | K39: =AVERAGE(K8:K37) -> 57027.358 | L39: =AVERAGE(L8:L37) -> 13172891 | M39: =SUM(J39:L39) -> 29655376 | N39: =M39-C39 -> 0
A40: Cobro % | B40: 1.62 | C40: =+C39*$B$41 -> 40034.758 | D40: =C40*1.16 -> 46440.319 | J40: =(+J39*$B$41) -> 22174.367 | K40: =(+K39*$B$41) -> 76.986933 | L40: =(+L39*$B$41) -> 17783.404 | M40: =SUM(J40:L40) -> 40034.758 | N40: =+C40/M40 -> 1
A41: Periodo | B41: =B40/360*B39/100 -> 0.00135 | D41: =D40-C40 -> 6405.5613 | M41: =C40/M40 -> 1
M45: =+'JUL24'!M41+'AGO24'!M41+'SEP24'!M40 -> 120296.21

Sheet OCT24
D1: Inicial | E1: 45565 | F1: 16529994 | G1: 57263.004 | H1: 13222888 | I1: =+F1+G1+H1 -> 29810144
D2: Final | E2: 45596 | F2: 16684171 | G2: 57381.074 | H2: 13477510 | I2: =+F2+G2+H2 -> 30219062
E4: =+E1 -> 45565 | F4: =+F1/$I1 -> 0.55450902 | G4: =+G1/$I1 -> 0.0019209234 | H4: =+H1/$I1 -> 0.44357006 | I4: =+F4+G4+H4 -> 1
E5: =+E2 -> 45596 | F5: =+F2/$I2 -> 0.5521075 | G5: =+G2/$I2 -> 0.001898837 | H5: =+H2/$I2 -> 0.44599366 | I5: =+F5+G5+H5 -> 1
A6: SISTEMA | E6: Promedio | F6: =AVERAGE(F4:F5) -> 0.55330826 | G6: =AVERAGE(G4:G5) -> 0.0019098802 | H6: =AVERAGE(H4:H5) -> 0.44478186
A7: CONTRATO | B7: FECHA | C7: MONTO | J7: VIIN000000000001 | K7: VIIN000000000003 | L7: VIIN000000000006
A8: 105433 | B8: 45566 | C8: 29846323 | J8: 16514217 | K8: 57002.902 | L8: 13275103 | M8: =SUM(J8:L8) -> 29846323 | N8: =+C8-M8 -> 0
A9: 105433 | B9: 45567 | C9: 29518554 | J9: 16332860 | K9: 56376.903 | L9: 13129317 | M9: =SUM(J9:L9) -> 29518554 | N9: =+C9-M9 -> 0
A10: 105433 | B10: 45568 | C10: 29424932 | J10: 16281058 | K10: 56198.095 | L10: 13087676 | M10: =SUM(J10:L10) -> 29424932 | N10: =+C10-M10 -> 0
A11: 105433 | B11: 45569 | C11: 29426002 | J11: 16281650 | K11: 56200.139 | L11: 13088152 | M11: =SUM(J11:L11) -> 29426002 | N11: =+C11-M11 -> 0
A12: 105433 | B12: 45570 | C12: 29426002 | J12: 16281650 | K12: 56200.139 | L12: 13088152 | M12: =SUM(J12:L12) -> 29426002 | N12: =+C12-M12 -> 0
A13: 105433 | B13: 45571 | C13: 29426002 | J13: 16281650 | K13: 56200.139 | L13: 13088152 | M13: =SUM(J13:L13) -> 29426002 | N13: =+C13-M13 -> 0
A14: 105433 | B14: 45572 | C14: 29434034 | J14: 16286094 | K14: 56215.479 | L14: 13091724 | M14: =SUM(J14:L14) -> 29434034 | N14: =+C14-M14 -> 0
A15: 105433 | B15: 45573 | C15: 29470456 | J15: 16306246 | K15: 56285.04 | L15: 13107924 | M15: =SUM(J15:L15) -> 29470456 | N15: =+C15-M15 -> 0
A16: 105433 | B16: 45574 | C16: 29701000 | J16: 16433809 | K16: 56725.352 | L16: 13210466 | M16: =SUM(J16:L16) -> 29701000 | N16: =+C16-M16 -> 0
A17: 105433 | B17: 45575 | C17: 29684116 | J17: 16424466 | K17: 56693.105 | L17: 13202956 | M17: =SUM(J17:L17) -> 29684116 | N17: =+C17-M17 -> 0
A18: 105433 | B18: 45576 | C18: 29483420 | J18: 16313420 | K18: 56309.801 | L18: 13113690 | M18: =SUM(J18:L18) -> 29483420 | N18: =+C18-M18 -> 0
A19: 105433 | B19: 45577 | C19: 29483420 | J19: 16313420 | K19: 56309.801 | L19: 13113690 | M19: =SUM(J19:L19) -> 29483420 | N19: =+C19-M19 -> 0
... A35: 105433 | B35: 45593 | C35: 30174875 | J35: 16696008 | K35: 57630.398 | L35: 13421237 | M35: =SUM(J35:L35) -> 30174875 | N35: =+C35-M35 -> 0
A36: 105433 | B36: 45594 | C36: 30205654 | J36: 16713038 | K36: 57689.181 | L36: 13434927 | M36: =SUM(J36:L36) -> 30205654
A37: 105433 | B37: 45595 | C37: 30255755 | J37: 16740759 | K37: 57784.868 | L37: 13457211 | M37: =SUM(J37:L37) -> 30255755 | N37: =+C37-M37 -> 0
A38: 105434 | B38: 45596 | C38: 30182416 | J38: 16700180 | K38: 57644.8 | L38: 13424591 | M38: =SUM(J38:L38) -> 30182416 | N38: =+C38-M38 -> 0
A40: Dias Prom | B40: =COUNT(B8:B38) -> 31 | C40: =AVERAGE(C8:C38) -> 29836776 | J40: =AVERAGE(J8:J38) -> 16508935 | K40: =AVERAGE(K8:K38) -> 56984.669 | L40: =AVERAGE(L8:L38) -> 13270857 | M40: =SUM(J40:L40) -> 29836776 | N40: =M40-C40 -> 0
A41: Cobro % | B41: 1.62 | C41: =+C40*$B$42 -> 41622.303 | D41: =C41*1.16 -> 48281.872 | J41: =(+J40*$B$42) -> 23029.964 | K41: =(+K40*$B$42) -> 79.493614 | L41: =(+L40*$B$42) -> 18512.845 | M41: =SUM(J41:L41) -> 41622.303 | N41: =+C41/M41 -> 1
A42: Periodo | B42: =B41/360*B40/100 -> 0.001395 | D42: =D41-C41 -> 6659.5685 | M42: =C41/M41 -> 1
M46: =+'JUL24'!M41+'AGO24'!M41+'OCT24'!M41 -> 121883.76
D47: =+C41+'NOV24'!C41 -> 82652.668

Sheet NOV24
D1: Inicial | E1: 45596 | F1: 16684171 | G1: 57381.074 | H1: 13477510 | I1: =+F1+G1+H1 -> 30219062
D2: Final | E2: 45991 | F2: 16799485 | G2: 57222.6 | H2: 13504601 | I2: =+F2+G2+H2 -> 30361308
E4: =+E1 -> 45596 | F4: =+F1/$I1 -> 0.5521075 | G4: =+G1/$I1 -> 0.001898837 | H4: =+H1/$I1 -> 0.44599366 | I4: =+F4+G4+H4 -> 1
E5: =+E2 -> 45991 | F5: =+F2/$I2 -> 0.55331887 | G5: =+G2/$I2 -> 0.0018847212 | H5: =+H2/$I2 -> 0.44479641 | I5: =+F5+G5+H5 -> 1
A6: SISTEMA | E6: Promedio | F6: =AVERAGE(F4:F5) -> 0.55271319 | G6: =AVERAGE(G4:G5) -> 0.0018917791 | H6: =AVERAGE(H4:H5) -> 0.44539503
A7: CONTRATO | B7: FECHA | C7: MONTO | J7: VIIN000000000001 | K7: VIIN000000000003 | L7: VIIN000000000006
A8: 105433 | B8: 45597 | C8: 30382512 | J8: 16792815 | K8: 57477.002 | L8: 13532220 | M8: =SUM(J8:L8) -> 30382512 | N8: =+C8-M8 -> 0
A9: 105433 | B9: 45598 | C9: 30382512 | J9: 16792815 | K9: 57477.002 | L9: 13532220 | M9: =SUM(J9:L9) -> 30382512 | N9: =+C9-M9 -> 0
A10: 105433 | B10: 45599 | C10: 30382512 | J10: 16792815 | K10: 57477.002 | L10: 13532220 | M10: =SUM(J10:L10) -> 30382512 | N10: =+C10-M10 -> 0
A11: 105433 | B11: 45600 | C11: 30223092 | J11: 16704701 | K11: 57175.414 | L11: 13461215 | M11: =SUM(J11:L11) -> 30223092 | N11: =+C11-M11 -> 0
A12: 105433 | B12: 45601 | C12: 30127532 | J12: 16651884 | K12: 56994.636 | L12: 13418653 | M12: =SUM(J12:L12) -> 30127532 | N12: =+C12-M12 -> 0
A13: 105433 | B13: 45602 | C13: 30134441 | J13: 16655703 | K13: 57007.706 | L13: 13421730 | M13: =SUM(J13:L13) -> 30134441 | N13: =+C13-M13 -> 0
A14: 105433 | B14: 45603 | C14: 29994722 | J14: 16578478 | K14: 56743.388 | L14: 13359500 | M14: =SUM(J14:L14) -> 29994722 | N14: =+C14-M14 -> 0
A15: 105433 | B15: 45604 | C15: 30280152 | J15: 16736239 | K15: 57283.359 | L15: 13486629 | M15: =SUM(J15:L15) -> 30280152 | N15: =+C15-M15 -> 0
A16: 105433 | B16: 45605 | C16: 30280152 | J16: 16736239 | K16: 57283.359 | L16: 13486629 | M16: =SUM(J16:L16) -> 30280152 | N16: =+C16-M16 -> 0
A17: 105433 | B17: 45971 | C17: 30280152 | J17: 16736239 | K17: 57283.359 | L17: 13486629 | M17: =SUM(J17:L17) -> 30280152 | N17: =+C17-M17 -> 0
A18: 105433 | B18: 45607 | C18: 30482469 | J18: 16848063 | K18: 57666.098 | L18: 13576740 | M18: =SUM(J18:L18) -> 30482469 | N18: =+C18-M18 -> 0
A19: 105433 | B19: 45608 | C19: 30676358 | J19: 16955228 | K19: 58032.893 | L19: 13663098 | M19: =SUM(J19:L19) -> 30676358 | N19: =+C19-M19 -> 0
... A37: 105433 | B37: 45626 | C37: 30361308 | J37: 16781095 | K37: 57436.889 | L37: 13522776 | M37: =SUM(J37:L37) -> 30361308 | N37: =+C37-M37 -> 0
N38: =+C38-M38 -> 0
A40: Dias Prom | B40: =COUNT(B8:B38) -> 30 | C40: =AVERAGE(C8:C38) -> 30392863 | J40: =AVERAGE(J8:J38) -> 16798536 | K40: =AVERAGE(K8:K38) -> 57496.583 | L40: =AVERAGE(L8:L38) -> 13536830 | M40: =SUM(J40:L40) -> 30392863 | N40: =M40-C40 -> 0
A41: Cobro % | B41: 1.62 | C41: =+C40*$B$42 -> 41030.365 | D41: =C41*1.16 -> 47595.223 | J41: =(+J40*$B$42) -> 22678.024 | K41: =(+K40*$B$42) -> 77.620387 | L41: =(+L40*$B$42) -> 18274.721 | M41: =SUM(J41:L41) -> 41030.365 | N41: =+C41/M41 -> 1
A42: Periodo | B42: =B41/360*B40/100 -> 0.00135 | D42: =D41-C41 -> 6564.8584 | M42: =C41/M41 -> 1
I44: Nov | J44: 22678.021 | K44: 77.620378 | L44: 18274.719
M46: =+'JUL24'!M41+'AGO24'!M41+'NOV24'!M41 -> 121291.82

Sheet DIC24
D1: Inicial | E1: 45991 | F1: 16799485 | G1: 57222.6 | H1: 13504601 | I1: =+F1+G1+H1 -> 30361308
D2: Final | E2: 46022 | F2: 17102155 | G2: 57786.717 | H2: 13740249 | I2: =+F2+G2+H2 -> 30900191
E4: =+E1 -> 45991 | F4: =+F1/$I1 -> 0.55331887 | G4: =+G1/$I1 -> 0.0018847212 | H4: =+H1/$I1 -> 0.44479641 | I4: =+F4+G4+H4 -> 1
E5: =+E2 -> 46022 | F5: =+F2/$I2 -> 0.55346439 | G5: =+G2/$I2 -> 0.0018701087 | H5: =+H2/$I2 -> 0.4446655 | I5: =+F5+G5+H5 -> 1
A6: SISTEMA | E6: Promedio | F6: =AVERAGE(F4:F5) -> 0.55339163 | G6: =AVERAGE(G4:G5) -> 0.0018774149 | H6: =AVERAGE(H4:H5) -> 0.44473095
A7: CONTRATO | B7: FECHA | C7: MONTO | J7: VIIN000000000001 | K7: VIIN000000000003 | L7: VIIN000000000006
A8: 105433 | B8: 45627 | C8: 30331505 | J8: 16785201 | K8: 56944.82 | L8: 13489359 | M8: =SUM(J8:L8) -> 30331505 | N8: =+C8-M8 -> 0
A9: 105433 | B9: 45628 | C9: 30372772 | J9: 16808038 | K9: 57022.295 | L9: 13507712 | M9: =SUM(J9:L9) -> 30372772 | N9: =+C9-M9 -> 0
A10: 105433 | B10: 45629 | C10: 30334431 | J10: 16786820 | K10: 56950.314 | L10: 13490660 | M10: =SUM(J10:L10) -> 30334431 | N10: =+C10-M10 -> 0
A11: 105433 | B11: 45630 | C11: 30264772 | J11: 16748271 | K11: 56819.534 | L11: 13459681 | M11: =SUM(J11:L11) -> 30264772 | N11: =+C11-M11 -> 0
A12: 105433 | B12: 45631 | C12: 30219229 | J12: 16723069 | K12: 56734.033 | L12: 13439427 | M12: =SUM(J12:L12) -> 30219229 | N12: =+C12-M12 -> 0
A13: 105433 | B13: 45632 | C13: 30205569 | J13: 16715509 | K13: 56708.386 | L13: 13433351 | M13: =SUM(J13:L13) -> 30205569 | N13: =+C13-M13 -> 0
A14: 105433 | B14: 45633 | C14: 30205569 | J14: 16715509 | K14: 56708.386 | L14: 13433351 | M14: =SUM(J14:L14) -> 30205569 | N14: =+C14-M14 -> 0
A15: 105433 | B15: 45634 | C15: 30205569 | J15: 16715509 | K15: 56708.386 | L15: 13433351 | M15: =SUM(J15:L15) -> 30205569 | N15: =+C15-M15 -> 0
A16: 105433 | B16: 45635 | C16: 30397741 | J16: 16821856 | K16: 57069.174 | L16: 13518816 | M16: =SUM(J16:L16) -> 30397741 | N16: =+C16-M16 -> 0
A17: 105433 | B17: 45636 | C17: 30217994 | J17: 16722385 | K17: 56731.713 | L17: 13438877 | M17: =SUM(J17:L17) -> 30217994 | N17: =+C17-M17 -> 0
A18: 105433 | B18: 45637 | C18: 30166371 | J18: 16693817 | K18: 56634.795 | L18: 13415919 | M18: =SUM(J18:L18) -> 30166371 | N18: =+C18-M18 -> 0
A19: 105433 | B19: 45638 | C19: 30166371 | J19: 16693817 | K19: 56634.795 | L19: 13415919 | M19: =SUM(J19:L19) -> 30166371 | N19: =+C19-M19 -> 0
... A35: 105433 | B35: 45654 | C35: 30387774 | J35: 16816340 | K35: 57050.462 | L35: 13514384 | M35: =SUM(J35:L35) -> 30387774 | N35: =+C35-M35 -> 0
A36: 105433 | B36: 45655 | C36: 30387774 | J36: 16816340 | K36: 57050.462 | L36: 13514384 | M36: =SUM(J36:L36) -> 30387774
A37: 105433 | B37: 45656 | C37: 30668468 | J37: 16971674 | K37: 57577.44 | L37: 13639217 | M37: =SUM(J37:L37) -> 30668468 | N37: =+C37-M37 -> 0
A38: 105433 | B38: 45657 | C38: 30994383 | J38: 17152032 | K38: 58189.318 | L38: 13784162 | M38: =SUM(J38:L38) -> 30994383 | N38: =+C38-M38 -> 0
A40: Dias Prom | B40: =COUNT(B8:B38) -> 31 | C40: =AVERAGE(C8:C38) -> 30288995 | J40: =AVERAGE(J8:J38) -> 16761676 | K40: =AVERAGE(K8:K38) -> 56865.011 | L40: =AVERAGE(L8:L38) -> 13470453 | M40: =SUM(J40:L40) -> 30288995 | N40: =M40-C40 -> 0
A41: Cobro % | B41: 1.62 | C41: =+C40*$B$42 -> 42253.147 | D41: =C41*1.16 -> 49013.651 | J41: =(+J40*$B$42) -> 23382.538 | K41: =(+K40*$B$42) -> 79.326691 | L41: =(+L40*$B$42) -> 18791.283 | M41: =SUM(J41:L41) -> 42253.147 | N41: =+C41/M41 -> 1
A42: Periodo | B42: =B41/360*B40/100 -> 0.001395 | D42: =D41-C41 -> 6760.5036 | M42: =C41/M41 -> 1
M46: =+'JUL24'!M41+'AGO24'!M41+'DIC24'!M41 -> 122514.6

Sheet ENE25
D1: Inicial | E1: 46022 | F1: 17102155 | G1: 57786.717 | H1: 13740249 | I1: =+F1+G1+H1 -> 30900191
D2: Final | E2: 45688 | F2: 17068883 | G2: 58336.232 | H2: 13743711 | I2: =+F2+G2+H2 -> 30870930
E4: =+E1 -> 46022 | F4: =+F1/$I1 -> 0.55346439 | G4: =+G1/$I1 -> 0.0018701087 | H4: =+H1/$I1 -> 0.4446655 | I4: =+F4+G4+H4 -> 1
E5: =+E2 -> 45688 | F5: =+F2/$I2 -> 0.55291121 | G5: =+G2/$I2 -> 0.0018896817 | H5: =+H2/$I2 -> 0.44519911 | I5: =+F5+G5+H5 -> 1
A6: SISTEMA | E6: Promedio | F6: =AVERAGE(F4:F5) -> 0.5531878 | G6: =AVERAGE(G4:G5) -> 0.0018798952 | H6: =AVERAGE(H4:H5) -> 0.44493231
A7: CONTRATO | B7: FECHA | C7: MONTO | J7: VIIN000000000001 | K7: VIIN000000000003 | L7: VIIN000000000006
A8: 105433 | B8: 45658 | C8: 30994383 | J8: 17145715 | K8: 58266.193 | L8: 13790402 | M8: =SUM(J8:L8) -> 30994383 | N8: =+C8-M8 -> 0
A9: 105433 | B9: 45659 | C9: 30740750 | J9: 17005408 | K9: 57789.39 | L9: 13677553 | M9: =SUM(J9:L9) -> 30740750 | N9: =+C9-M9 -> 0
A10: 105433 | B10: 45660 | C10: 30760448 | J10: 17016304 | K10: 57826.419 | L10: 13686317 | M10: =SUM(J10:L10) -> 30760448 | N10: =+C10-M10 -> 0
A11: 105433 | B11: 45661 | C11: 30760448 | J11: 17016304 | K11: 57826.419 | L11: 13686317 | M11: =SUM(J11:L11) -> 30760448 | N11: =+C11-M11 -> 0
A12: 105433 | B12: 45662 | C12: 30760448 | J12: 17016304 | K12: 57826.419 | L12: 13686317 | M12: =SUM(J12:L12) -> 30760448 | N12: =+C12-M12 -> 0
A13: 105433 | B13: 45663 | C13: 30410394 | J13: 16822659 | K13: 57168.355 | L13: 13530567 | M13: =SUM(J13:L13) -> 30410394 | N13: =+C13-M13 -> 0
A14: 105433 | B14: 45664 | C14: 30422400 | J14: 16829301 | K14: 57190.925 | L14: 13535909 | M14: =SUM(J14:L14) -> 30422400 | N14: =+C14-M14 -> 0
A15: 105433 | B15: 45665 | C15: 30549224 | J15: 16899458 | K15: 57429.34 | L15: 13592337 | M15: =SUM(J15:L15) -> 30549224 | N15: =+C15-M15 -> 0
A16: 105433 | B16: 45666 | C16: 30578030 | J16: 16915393 | K16: 57483.493 | L16: 13605154 | M16: =SUM(J16:L16) -> 30578030 | N16: =+C16-M16 -> 0
A17: 105433 | B17: 45667 | C17: 30802922 | J17: 17039801 | K17: 57906.267 | L17: 13705215 | M17: =SUM(J17:L17) -> 30802922 | N17: =+C17-M17 -> 0
A18: 105433 | B18: 45668 | C18: 30802922 | J18: 17039801 | K18: 57906.267 | L18: 13705215 | M18: =SUM(J18:L18) -> 30802922 | N18: =+C18-M18 -> 0
A19: 105433 | B19: 45669 | C19: 30802922 | J19: 17039801 | K19: 57906.267 | L19: 13705215 | M19: =SUM(J19:L19) -> 30802922 | N19: =+C19-M19 -> 0
... A35: 105433 | B35: 45685 | C35: 30816178 | J35: 17047134 | K35: 57931.186 | L35: 13711113 | M35: =SUM(J35:L35) -> 30816178 | N35: =+C35-M35 -> 0
A36: 105433 | B36: 45686 | C36: 30814671 | J36: 17046300 | K36: 57928.352 | L36: 13710442 | M36: =SUM(J36:L36) -> 30814671
A37: 105433 | B37: 45687 | C37: 30890003 | J37: 17087973 | K37: 58069.969 | L37: 13743960 | M37: =SUM(J37:L37) -> 30890003 | N37: =+C37-M37 -> 0
A38: 105433 | B38: 45688 | C38: 31041507 | J38: 17171783 | K38: 58354.781 | L38: 13811369 | M38: =SUM(J38:L38) -> 31041507 | N38: =+C38-M38 -> 0
A40: Dias Prom | B40: =COUNT(B8:B38) -> 31 | C40: =AVERAGE(C8:C38) -> 30708165 | J40: =AVERAGE(J8:J38) -> 16987382 | K40: =AVERAGE(K8:K38) -> 57728.134 | L40: =AVERAGE(L8:L38) -> 13663055 | M40: =SUM(J40:L40) -> 30708165 | N40: =M40-C40 -> 0
A41: Cobro % | B41: 1.62 | C41: =+C40*$B$42 -> 42837.891 | D41: =C41*1.16 -> 49691.953 | J41: =(+J40*$B$42) -> 23697.398 | K41: =(+K40*$B$42) -> 80.530747 | L41: =(+L40*$B$42) -> 19059.962 | M41: =SUM(J41:L41) -> 42837.891 | N41: =+C41/M41 -> 1
A42: Periodo | B42: =B41/360*B40/100 -> 0.001395 | D42: =D41-C41 -> 6854.0625 | M42: =C41/M41 -> 1
M46: =+'JUL24'!M41+'AGO24'!M41+'ENE25'!M41 -> 123099.34

Sheet FEB25
D1: Inicial | E1: 45688 | F1: 17068883 | G1: 58336.232 | H1: 13743711 | I1: =+F1+G1+H1 -> 30870930
D2: Final | E2: 45716 | F2: 17175974 | G2: 58761.67 | H2: 13872700 | I2: =+F2+G2+H2 -> 31107436
E4: =+E1 -> 45688 | F4: =+F1/$I1 -> 0.55291121 | G4: =+G1/$I1 -> 0.0018896817 | H4: =+H1/$I1 -> 0.44519911 | I4: =+F4+G4+H4 -> 1
E5: =+E2 -> 45716 | F5: =+F2/$I2 -> 0.55215011 | G5: =+G2/$I2 -> 0.0018889911 | H5: =+H2/$I2 -> 0.4459609 | I5: =+F5+G5+H5 -> 1
A6: SISTEMA | E6: Promedio | F6: =AVERAGE(F4:F5) -> 0.55253066 | G6: =AVERAGE(G4:G5) -> 0.0018893364 | H6: =AVERAGE(H4:H5) -> 0.44558001
A7: CONTRATO | B7: FECHA | C7: MONTO | J7: VIIN000000000001 | K7: VIIN000000000003 | L7: VIIN000000000006
A8: 105433 | B8: 45689 | C8: 31041507 | J8: 17151384 | K8: 58647.849 | L8: 13831475 | M8: =SUM(J8:L8) -> 31041507 | N8: =+C8-M8 -> 0
A9: 105433 | B9: 45690 | C9: 31041507 | J9: 17151384 | K9: 58647.849 | L9: 13831475 | M9: =SUM(J9:L9) -> 31041507 | N9: =+C9-M9 -> 0
A10: 105433 | B10: 45691 | C10: 31041507 | J10: 17151384 | K10: 58647.849 | L10: 13831475 | M10: =SUM(J10:L10) -> 31041507 | N10: =+C10-M10 -> 0
A11: 105433 | B11: 45692 | C11: 30753492 | J11: 16992247 | K11: 58103.692 | L11: 13703141 | M11: =SUM(J11:L11) -> 30753492 | N11: =+C11-M11 -> 0
A12: 105433 | B12: 45693 | C12: 30868215 | J12: 17055635 | K12: 58320.444 | L12: 13754260 | M12: =SUM(J12:L12) -> 30868215 | N12: =+C12-M12 -> 0
A13: 105433 | B13: 45694 | C13: 30730214 | J13: 16979385 | K13: 58059.712 | L13: 13692769 | M13: =SUM(J13:L13) -> 30730214 | N13: =+C13-M13 -> 0
A14: 105433 | B14: 45695 | C14: 30822269 | J14: 17030249 | K14: 58233.635 | L14: 13733787 | M14: =SUM(J14:L14) -> 30822269 | N14: =+C14-M14 -> 0
A15: 105433 | B15: 45696 | C15: 30822269 | J15: 17030249 | K15: 58233.635 | L15: 13733787 | M15: =SUM(J15:L15) -> 30822269 | N15: =+C15-M15 -> 0
A16: 105433 | B16: 45697 | C16: 30822269 | J16: 17030249 | K16: 58233.635 | L16: 13733787 | M16: =SUM(J16:L16) -> 30822269 | N16: =+C16-M16 -> 0
A17: 105433 | B17: 45698 | C17: 30945199 | J17: 17098171 | K17: 58465.892 | L17: 13788562 | M17: =SUM(J17:L17) -> 30945199 | N17: =+C17-M17 -> 0
A18: 105433 | B18: 45699 | C18: 30860535 | J18: 17051392 | K18: 58305.932 | L18: 13750837 | M18: =SUM(J18:L18) -> 30860535 | N18: =+C18-M18 -> 0
A19: 105433 | B19: 45700 | C19: 30902885 | J19: 17074792 | K19: 58385.947 | L19: 13769708 | M19: =SUM(J19:L19) -> 30902885 | N19: =+C19-M19 -> 0
... A35: 105433 | B35: 45716 | C35: 31094112 | J35: 17180450 | K35: 58747.238 | L35: 13854915 | M35: =SUM(J35:L35) -> 31094112 | N35: =+C35-M35 -> 0
A37: Dias Prom | B37: =COUNT(B8:B35) -> 28 | C37: =AVERAGE(C8:C35) -> 30902879 | J37: =AVERAGE(J8:J35) -> 17074788 | K37: =AVERAGE(K8:K35) -> 58385.935 | L37: =AVERAGE(L8:L35) -> 13769705 | M37: =SUM(J37:L37) -> 30902879 | N37: =M37-C37 -> 0
A38: Cobro % | B38: 1.62 | C38: =+C37*$B$39 -> 38937.628 | D38: =C38*1.16 -> 45167.648 | J38: =(+J37*$B$39) -> 21514.233 | K38: =(+K37*$B$39) -> 73.566278 | L38: =(+L37*$B$39) -> 17349.828 | M38: =SUM(J38:L38) -> 38937.628 | N38: =+C38/M38 -> 1
A39: Periodo | B39: =B38/360*B37/100 -> 0.00126 | D39: =D38-C38 -> 6230.0204 | M39: =C38/M38 -> 1
J43: Cobrado en abril | M43: =+'JUL24'!M41+'AGO24'!M41+'FEB25'!M38 -> 119199.08

Sheet MAR25
D1: Inicial | E1: 45716 | F1: 17175974 | G1: 58761.67 | H1: 13872700 | I1: =+F1+G1+H1 -> 31107436
D2: Final | E2: 45747 | F2: 17148448 | G2: 59082.306 | H2: 13903727 | I2: =+F2+G2+H2 -> 31111258
E4: =+E1 -> 45716 | F4: =+F1/$I1 -> 0.55215011 | G4: =+G1/$I1 -> 0.0018889911 | H4: =+H1/$I1 -> 0.4459609 | I4: =+F4+G4+H4 -> 1
E5: =+E2 -> 45747 | F5: =+F2/$I2 -> 0.55119752 | G5: =+G2/$I2 -> 0.0018990651 | H5: =+H2/$I2 -> 0.44690341 | I5: =+F5+G5+H5 -> 1
A6: SISTEMA | E6: Promedio | F6: =AVERAGE(F4:F5) -> 0.55167381 | G6: =AVERAGE(G4:G5) -> 0.0018940281 | H6: =AVERAGE(H4:H5) -> 0.44643216
A7: CONTRATO | B7: FECHA | C7: MONTO | J7: VIIN000000000001 | K7: VIIN000000000003 | L7: VIIN000000000006
A8: 105433 | B8: 45717 | C8: 31094112 | J8: 17153807 | K8: 58893.122 | L8: 13881411 | M8: =SUM(J8:L8) -> 31094112 | N8: =+C8-M8 -> 0
A9: 105433 | B9: 45718 | C9: 31094112 | J9: 17153807 | K9: 58893.122 | L9: 13881411 | M9: =SUM(J9:L9) -> 31094112 | N9: =+C9-M9 -> 0
A10: 105433 | B10: 45719 | C10: 31228571 | J10: 17227985 | K10: 59147.791 | L10: 13941438 | M10: =SUM(J10:L10) -> 31228571 | N10: =+C10-M10 -> 0
A11: 105433 | B11: 45720 | C11: 31190304 | J11: 17206874 | K11: 59075.312 | L11: 13924355 | M11: =SUM(J11:L11) -> 31190304 | N11: =+C11-M11 -> 0
A12: 105433 | B12: 45721 | C12: 30904902 | J12: 17049425 | K12: 58534.753 | L12: 13796942 | M12: =SUM(J12:L12) -> 30904902 | N12: =+C12-M12 -> 0
A13: 105433 | B13: 45722 | C13: 30906997 | J13: 17050581 | K13: 58538.722 | L13: 13797877 | M13: =SUM(J13:L13) -> 30906997 | N13: =+C13-M13 -> 0
A14: 105433 | B14: 45723 | C14: 30957153 | J14: 17078251 | K14: 58633.718 | L14: 13820269 | M14: =SUM(J14:L14) -> 30957153 | N14: =+C14-M14 -> 0
A15: 105433 | B15: 45724 | C15: 30957153 | J15: 17078251 | K15: 58633.718 | L15: 13820269 | M15: =SUM(J15:L15) -> 30957153 | N15: =+C15-M15 -> 0
A16: 105433 | B16: 45725 | C16: 30957153 | J16: 17078251 | K16: 58633.718 | L16: 13820269 | M16: =SUM(J16:L16) -> 30957153 | N16: =+C16-M16 -> 0
A17: 105433 | B17: 45726 | C17: 31024205 | J17: 17115241 | K17: 58760.716 | L17: 13850203 | M17: =SUM(J17:L17) -> 31024205 | N17: =+C17-M17 -> 0
A18: 105433 | B18: 45727 | C18: 30886148 | J18: 17039079 | K18: 58499.232 | L18: 13788569 | M18: =SUM(J18:L18) -> 30886148 | N18: =+C18-M18 -> 0
A19: 105433 | B19: 45728 | C19: 30851181 | J19: 17019789 | K19: 58433.004 | L19: 13772959 | M19: =SUM(J19:L19) -> 30851181 | N19: =+C19-M19 -> 0
... A38: 105433 | B38: 45747 | C38: 31137456 | J38: 17177719 | K38: 58975.217 | L38: 13900762 | M38: =SUM(J38:L38) -> 31137456 | N38: =+C38-M38 -> 0
A40: Dias Prom | B40: =COUNT(B8:B38) -> 31 | C40: =AVERAGE(C8:C38) -> 30902079 | J40: =AVERAGE(J8:J38) -> 17047868 | K40: =AVERAGE(K8:K38) -> 58529.407 | L40: =AVERAGE(L8:L38) -> 13795682 | M40: =SUM(J40:L40) -> 30902079 | N40: =M40-C40 -> 0
A41: Cobro % | B41: 1.62 | C41: =+C40*$B$42 -> 43108.4 | D41: =C41*1.16 -> 50005.744 | J41: =(+J40*$B$42) -> 23781.776 | K41: =(+K40*$B$42) -> 81.648522 | L41: =(+L40*$B$42) -> 19244.976 | M41: =SUM(J41:L41) -> 43108.4 | N41: =+C41/M41 -> 1
A42: Periodo | B42: =B41/360*B40/100 -> 0.001395 | D42: =D41-C41 -> 6897.344 | M42: =C41/M41 -> 1
J46: Cobrado en abril | M46: =+'JUL24'!M41+'AGO24'!M41+'MAR25'!M41 -> 123369.85

Sheet ABR25
D1: Inicial | E1: 45747 | F1: 17148448 | G1: 59082.306 | H1: 13903727 | I1: =+F1+G1+H1 -> 31111258
D2: Final | E2: 45777 | F2: 16754159 | G2: 59947.59 | H2: 13685432 | I2: =+F2+G2+H2 -> 30499538
E4: =+E1 -> 45747 | F4: =+F1/$I1 -> 0.55119752 | G4: =+G1/$I1 -> 0.0018990651 | H4: =+H1/$I1 -> 0.44690341 | I4: =+F4+G4+H4 -> 1
E5: =+E2 -> 45777 | F5: =+F2/$I2 -> 0.549325 | G5: =+G2/$I2 -> 0.0019655245 | H5: =+H2/$I2 -> 0.44870948 | I5: =+F5+G5+H5 -> 1
A6: SISTEMA | E6: Promedio | F6: =AVERAGE(F4:F5) -> 0.55026126 | G6: =AVERAGE(G4:G5) -> 0.0019322948 | H6: =AVERAGE(H4:H5) -> 0.44780645
A7: CONTRATO | B7: FECHA | C7: MONTO | J7: VIIN000000000001 | K7: VIIN000000000003 | L7: VIIN000000000006
A8: 105433 | B8: 45748 | C8: 30975441 | J8: 17044585 | K8: 59853.684 | L8: 13871002 | M8: =SUM(J8:L8) -> 30975441 | N8: =+C8-M8 -> 0
A9: 105433 | B9: 45749 | C9: 31130192 | J9: 17129738 | K9: 60152.708 | L9: 13940300 | M9: =SUM(J9:L9) -> 31130192 | N9: =+C9-M9 -> 0
A10: 105433 | B10: 45750 | C10: 30720928 | J10: 16904536 | K10: 59361.889 | L10: 13757029 | M10: =SUM(J10:L10) -> 30720928 | N10: =+C10-M10 -> 0
A11: 105433 | B11: 45751 | C11: 30963383 | J11: 17037950 | K11: 59830.385 | L11: 13865603 | M11: =SUM(J11:L11) -> 30963383 | N11: =+C11-M11 -> 0
A12: 105433 | B12: 45752 | C12: 30963383 | J12: 17037950 | K12: 59830.385 | L12: 13865603 | M12: =SUM(J12:L12) -> 30963383 | N12: =+C12-M12 -> 0
A13: 105433 | B13: 45753 | C13: 30963383 | J13: 17037950 | K13: 59830.385 | L13: 13865603 | M13: =SUM(J13:L13) -> 30963383 | N13: =+C13-M13 -> 0
A14: 105433 | B14: 45754 | C14: 31033157 | J14: 17076344 | K14: 59965.208 | L14: 13896848 | M14: =SUM(J14:L14) -> 31033157 | N14: =+C14-M14 -> 0
A15: 105433 | B15: 45755 | C15: 31101994 | J15: 17114222 | K15: 60098.222 | L15: 13927673 | M15: =SUM(J15:L15) -> 31101994 | N15: =+C15-M15 -> 0
A16: 105433 | B16: 45756 | C16: 30704692 | J16: 16895602 | K16: 59330.517 | L16: 13749759 | M16: =SUM(J16:L16) -> 30704692 | N16: =+C16-M16 -> 0
A17: 105433 | B17: 45757 | C17: 30810606 | J17: 16953883 | K17: 59535.175 | L17: 13797188 | M17: =SUM(J17:L17) -> 30810606 | N17: =+C17-M17 -> 0
A18: 105433 | B18: 45758 | C18: 30762055 | J18: 16927167 | K18: 59441.36 | L18: 13775447 | M18: =SUM(J18:L18) -> 30762055 | N18: =+C18-M18 -> 0
A19: 105433 | B19: 45759 | C19: 30762055 | J19: 16927167 | K19: 59441.36 | L19: 13775447 | M19: =SUM(J19:L19) -> 30762055 | N19: =+C19-M19 -> 0
... A37: 105433 | B37: 45777 | C37: 31015611 | J37: 17066689 | K37: 59931.305 | L37: 13888991 | M37: =SUM(J37:L37) -> 31015611 | N37: =+C37-M37 -> 0
